Workbook

Sheet Product and deployment architec
A1: Product and deployment architecture
A5: Expert | B5: Excellent | C5: Very good | D5: Good | E5: Above Average | F5: Average and Below
B6: =IF('Skill Index'!C4=9,'Skill Index'!A4,"") | C6: =IF('Skill Index'!C4=8,'Skill Index'!A4,"") -> Ankit Rajput | D6: =IF('Skill Index'!C4=7,'Skill Index'!A4,"") | E6: =IF('Skill Index'!C4=6,'Skill Index'!A4,"") | F6: =IF('Skill Index'!C4<6,'Skill Index'!A4,"")
B7: =IF('Skill Index'!C5=9,'Skill Index'!A5,"") | C7: =IF('Skill Index'!C5=8,'Skill Index'!A5,"") | D7: =IF('Skill Index'!C5=7,'Skill Index'!A5,"") | E7: =IF('Skill Index'!C5=6,'Skill Index'!A5,"") -> Anusha Gunda | F7: =IF('Skill Index'!C5<6,'Skill Index'!A5,"")
B8: =IF('Skill Index'!C6=9,'Skill Index'!A6,"") | C8: =IF('Skill Index'!C6=8,'Skill Index'!A6,"") | D8: =IF('Skill Index'!C6=7,'Skill Index'!A6,"") | E8: =IF('Skill Index'!C6=6,'Skill Index'!A6,"") | F8: =IF('Skill Index'!C6<6,'Skill Index'!A6,"") -> Arun Kumar
B9: =IF('Skill Index'!C7=9,'Skill Index'!A7,"") | C9: =IF('Skill Index'!C7=8,'Skill Index'!A7,"") -> Ashraya H D | D9: =IF('Skill Index'!C7=7,'Skill Index'!A7,"") | E9: =IF('Skill Index'!C7=6,'Skill Index'!A7,"") | F9: =IF('Skill Index'!C7<6,'Skill Index'!A7,"")
B10: =IF('Skill Index'!C8=9,'Skill Index'!A8,"") | C10: =IF('Skill Index'!C8=8,'Skill Index'!A8,"") | D10: =IF('Skill Index'!C8=7,'Skill Index'!A8,"") | E10: =IF('Skill Index'!C8=6,'Skill Index'!A8,"") -> Jeet Doshi | F10: =IF('Skill Index'!C8<6,'Skill Index'!A8,"")
B11: =IF('Skill Index'!C9=9,'Skill Index'!A9,"") | C11: =IF('Skill Index'!C9=8,'Skill Index'!A9,"") | D11: =IF('Skill Index'!C9=7,'Skill Index'!A9,"") | E11: =IF('Skill Index'!C9=6,'Skill Index'!A9,"") | F11: =IF('Skill Index'!C9<6,'Skill Index'!A9,"") -> Mahesh Kumar
B12: =IF('Skill Index'!C10=9,'Skill Index'!A10,"") | C12: =IF('Skill Index'!C10=8,'Skill Index'!A10,"") | D12: =IF('Skill Index'!C10=7,'Skill Index'!A10,"") -> Nilekha Repaka | E12: =IF('Skill Index'!C10=6,'Skill Index'!A10,"") | F12: =IF('Skill Index'!C10<6,'Skill Index'!A10,"")
B13: =IF('Skill Index'!C11=9,'Skill Index'!A11,"") | C13: =IF('Skill Index'!C11=8,'Skill Index'!A11,"") -> Pawan Rathore | D13: =IF('Skill Index'!C11=7,'Skill Index'!A11,"") | E13: =IF('Skill Index'!C11=6,'Skill Index'!A11,"") | F13: =IF('Skill Index'!C11<6,'Skill Index'!A11,"")
B14: =IF('Skill Index'!C12=9,'Skill Index'!A12,"") | C14: =IF('Skill Index'!C12=8,'Skill Index'!A12,"") | D14: =IF('Skill Index'!C12=7,'Skill Index'!A12,"") -> Priyesh Tiwari | E14: =IF('Skill Index'!C12=6,'Skill Index'!A12,"") | F14: =IF('Skill Index'!C12<6,'Skill Index'!A12,"")
B15: =IF('Skill Index'!C13=9,'Skill Index'!A13,"") | C15: =IF('Skill Index'!C13=8,'Skill Index'!A13,"") | D15: =IF('Skill Index'!C13=7,'Skill Index'!A13,"") | E15: =IF('Skill Index'!C13=6,'Skill Index'!A13,"") -> Rahul Kumar | F15: =IF('Skill Index'!C13<6,'Skill Index'!A13,"")
B16: =IF('Skill Index'!C14=9,'Skill Index'!A14,"") | C16: =IF('Skill Index'!C14=8,'Skill Index'!A14,"") | D16: =IF('Skill Index'!C14=7,'Skill Index'!A14,"") | E16: =IF('Skill Index'!C14=6,'Skill Index'!A14,"") -> Ramkrishna Kadiya | F16: =IF('Skill Index'!C14<6,'Skill Index'!A14,"")
B17: =IF('Skill Index'!C15=9,'Skill Index'!A15,"") | C17: =IF('Skill Index'!C15=8,'Skill Index'!A15,"") | D17: =IF('Skill Index'!C15=7,'Skill Index'!A15,"") | E17: =IF('Skill Index'!C15=6,'Skill Index'!A15,"") -> Revanth Anguluri | F17: =IF('Skill Index'!C15<6,'Skill Index'!A15,"")
... B22: =IF('Skill Index'!C20=9,'Skill Index'!A20,"") | C22: =IF('Skill Index'!C20=8,'Skill Index'!A20,"") | D22: =IF('Skill Index'!C20=7,'Skill Index'!A20,"") | E22: =IF('Skill Index'!C20=6,'Skill Index'!A20,"") | F22: =IF('Skill Index'!C20<6,'Skill Index'!A20,"") -> Swetha KJ

Sheet Support Collaboration_x0009_
A1: Support Collaboration
A5: Expert | B5: Excellent | C5: Very good | D5: Good | E5: Above Average | F5: Average and Below
A6: =IF('Skill Index'!D4=10,'Skill Index'!A4,"") | B6: =IF('Skill Index'!D4=9,'Skill Index'!A4,"") | C6: =IF('Skill Index'!D4=8,'Skill Index'!A4,"") -> Ankit Rajput | D6: =IF('Skill Index'!D4=7,'Skill Index'!A4,"") | E6: =IF('Skill Index'!D4=6,'Skill Index'!A4,"") | F6: =IF('Skill Index'!D4<6,'Skill Index'!A4,"")
A7: =IF('Skill Index'!D5=10,'Skill Index'!A5,"") | B7: =IF('Skill Index'!D5=9,'Skill Index'!A5,"") | C7: =IF('Skill Index'!D5=8,'Skill Index'!A5,"") | D7: =IF('Skill Index'!D5=7,'Skill Index'!A5,"") | E7: =IF('Skill Index'!D5=6,'Skill Index'!A5,"") -> Anusha Gunda | F7: =IF('Skill Index'!D5<6,'Skill Index'!A5,"")
A8: =IF('Skill Index'!D6=10,'Skill Index'!A6,"") | B8: =IF('Skill Index'!D6=9,'Skill Index'!A6,"") | C8: =IF('Skill Index'!D6=8,'Skill Index'!A6,"") | D8: =IF('Skill Index'!D6=7,'Skill Index'!A6,"") | E8: =IF('Skill Index'!D6=6,'Skill Index'!A6,"") | F8: =IF('Skill Index'!D6<6,'Skill Index'!A6,"") -> Arun Kumar
A9: =IF('Skill Index'!D7=10,'Skill Index'!A7,"") | B9: =IF('Skill Index'!D7=9,'Skill Index'!A7,"") | C9: =IF('Skill Index'!D7=8,'Skill Index'!A7,"") -> Ashraya H D | D9: =IF('Skill Index'!D7=7,'Skill Index'!A7,"") | E9: =IF('Skill Index'!D7=6,'Skill Index'!A7,"") | F9: =IF('Skill Index'!D7<6,'Skill Index'!A7,"")
A10: =IF('Skill Index'!D8=10,'Skill Index'!A8,"") | B10: =IF('Skill Index'!D8=9,'Skill Index'!A8,"") | C10: =IF('Skill Index'!D8=8,'Skill Index'!A8,"") | D10: =IF('Skill Index'!D8=7,'Skill Index'!A8,"") -> Jeet Doshi | E10: =IF('Skill Index'!D8=6,'Skill Index'!A8,"") | F10: =IF('Skill Index'!D8<6,'Skill Index'!A8,"")
A11: =IF('Skill Index'!D9=10,'Skill Index'!A9,"") | B11: =IF('Skill Index'!D9=9,'Skill Index'!A9,"") | C11: =IF('Skill Index'!D9=8,'Skill Index'!A9,"") | D11: =IF('Skill Index'!D9=7,'Skill Index'!A9,"") | E11: =IF('Skill Index'!D9=6,'Skill Index'!A9,"") | F11: =IF('Skill Index'!D9<6,'Skill Index'!A9,"") -> Mahesh Kumar
A12: =IF('Skill Index'!D10=10,'Skill Index'!A10,"") | B12: =IF('Skill Index'!D10=9,'Skill Index'!A10,"") | C12: =IF('Skill Index'!D10=8,'Skill Index'!A10,"") -> Nilekha Repaka | D12: =IF('Skill Index'!D10=7,'Skill Index'!A10,"") | E12: =IF('Skill Index'!D10=6,'Skill Index'!A10,"") | F12: =IF('Skill Index'!D10<6,'Skill Index'!A10,"")
A13: =IF('Skill Index'!D11=10,'Skill Index'!A11,"") | B13: =IF('Skill Index'!D11=9,'Skill Index'!A11,"") | C13: =IF('Skill Index'!D11=8,'Skill Index'!A11,"") -> Pawan Rathore | D13: =IF('Skill Index'!D11=7,'Skill Index'!A11,"") | E13: =IF('Skill Index'!D11=6,'Skill Index'!A11,"") | F13: =IF('Skill Index'!D11<6,'Skill Index'!A11,"")
A14: =IF('Skill Index'!D12=10,'Skill Index'!A12,"") | B14: =IF('Skill Index'!D12=9,'Skill Index'!A12,"") | C14: =IF('Skill Index'!D12=8,'Skill Index'!A12,"") -> Priyesh Tiwari | D14: =IF('Skill Index'!D12=7,'Skill Index'!A12,"") | E14: =IF('Skill Index'!D12=6,'Skill Index'!A12,"") | F14: =IF('Skill Index'!D12<6,'Skill Index'!A12,"")
A15: =IF('Skill Index'!D13=10,'Skill Index'!A13,"") | B15: =IF('Skill Index'!D13=9,'Skill Index'!A13,"") | C15: =IF('Skill Index'!D13=8,'Skill Index'!A13,"") -> Rahul Kumar | D15: =IF('Skill Index'!D13=7,'Skill Index'!A13,"") | E15: =IF('Skill Index'!D13=6,'Skill Index'!A13,"") | F15: =IF('Skill Index'!D13<6,'Skill Index'!A13,"")
A16: =IF('Skill Index'!D14=10,'Skill Index'!A14,"") | B16: =IF('Skill Index'!D14=9,'Skill Index'!A14,"") | C16: =IF('Skill Index'!D14=8,'Skill Index'!A14,"") | D16: =IF('Skill Index'!D14=7,'Skill Index'!A14,"") -> Ramkrishna Kadiya | E16: =IF('Skill Index'!D14=6,'Skill Index'!A14,"") | F16: =IF('Skill Index'!D14<6,'Skill Index'!A14,"")
A17: =IF('Skill Index'!D15=10,'Skill Index'!A15,"") | B17: =IF('Skill Index'!D15=9,'Skill Index'!A15,"") | C17: =IF('Skill Index'!D15=8,'Skill Index'!A15,"") | D17: =IF('Skill Index'!D15=7,'Skill Index'!A15,"") | E17: =IF('Skill Index'!D15=6,'Skill Index'!A15,"") -> Revanth Anguluri | F17: =IF('Skill Index'!D15<6,'Skill Index'!A15,"")
... A22: =IF('Skill Index'!D20=10,'Skill Index'!A20,"") | B22: =IF('Skill Index'!D20=9,'Skill Index'!A20,"") | C22: =IF('Skill Index'!D20=8,'Skill Index'!A20,"") | D22: =IF('Skill Index'!D20=7,'Skill Index'!A20,"") | E22: =IF('Skill Index'!D20=6,'Skill Index'!A20,"") -> Swetha KJ | F22: =IF('Skill Index'!D20<6,'Skill Index'!A20,"")

Sheet Skill Index
A1: Name | B1: Score | C1: Product and deployment architecture | D1: Support Collaboration | E1: Robot/Assistant | G1: Studio Family | I1: Orchestrator | M1: HAA | N1: Action Center | P1: AI Center/ DU | Q1: Test Suite | S1: Insights | U1: Task Mining | V1: Process Mining | W1: Communications Mining | X1: Automation Ops | Y1: Integration Services | Z1: Data Services | AA1: Apps | AB1: Automation Hub | AC1: Computer Vision | AE1: Clipboard AI | AF1: Automation Suite | AN1: License Management | AO1: DevOps | AP1: Linux | AQ1: Infra skills | AR1: SQL Server | AS1: Kubernetes | AT1: AWS | AU1: Azure | AV1: GCP | AW1: Saas Adoption | AZ1: GenAI Awareness
E2: Install/Upgrade/Config | F2: Feature/Delivery | G2: Install/Upgrade/Config | H2: Feature/Delivery | I2: Install/Upgrade/Config | K2: Integrations (Cred Vault, AD) | L2: Feature/Delivery | M2: Install/Upgrade/Config | N2: Install/Upgrade/Config | O2: Feature/Delivery | P2: Feature/Delivery | Q2: Install/Upgrade/Config | R2: Feature/Delivery | S2: Install/Upgrade/Config | T2: Feature/Delivery | U2: Feature/Delivery | V2: Feature/Delivery | W2: Feature/Delivery | X2: Feature/Delivery | Y2: Feature/Delivery | Z2: Feature/Delivery | AA2: Feature/Delivery | AB2: Feature/Delivery | AC2: Install/Upgrade/Config | AD2: Feature/Delivery | AE2: Feature/Delivery | AF2: PaaS | AJ2: IaaS | AW2: Migration Persuasion | AX2: Security And Architecture | AY2: Migration | AZ2: Security And Architecture | BA2: Functionality
A3: Team Average | I3: Windows(msi) | J3: PaaS | AF3: Install | AG3: Upgrade | AH3: Migration | AI3: Configuration / Monitoring | AJ3: Install | AK3: Upgrade | AL3: Migration | AM3: Configuration / Monitoring
A4: Ankit Rajput | C4: 8 | D4: 8 | E4: 8 | F4: 6 | G4: 8 | H4: 6 | I4: 9 | J4: 8 | K4: 6 | L4: 7 | M4: 2 | N4: 8 | O4: 8 | P4: 3 | Q4: 7 | R4: 6 | S4: 6 | T4: 6 | U4: 4 | V4: 6 | W4: 3 | X4: 6 | Y4: 6 | Z4: 2 | AA4: 2 | AB4: 5 | AC4: 3 | AD4: 3 | AE4: 3 | AF4: 1 | AG4: 1 | AH4: 1 | AI4: 1 | AJ4: 3 | AK4: 3 | AL4: 1 | AM4: 3 | AN4: 7 | AO4: 5 | AP4: 2 | AQ4: 6 | AR4: 7 | AS4: 2 | AT4: 6 | AU4: 5 | AV4: 4 | AW4: 9 | AX4: 8 | AY4: 7 | AZ4: 7 | BA4: 5
A5: Anusha Gunda | C5: 6 | D5: 6 | E5: 7 | F5: 7 | G5: 7 | H5: 6 | I5: 8 | J5: 4 | K5: 4 | L5: 8 | M5: 4 | N5: 6 | O5: 8 | P5: 6 | Q5: 6 | R5: 6 | S5: 6 | T5: 7 | U5: 6 | V5: 4 | W5: 3 | X5: 3 | Y5: 3 | Z5: 3 | AA5: 6 | AB5: 6 | AC5: 5 | AD5: 6 | AE5: 3 | AF5: 1 | AG5: 1 | AH5: 1 | AI5: 1 | AJ5: 4 | AK5: 1 | AL5: 1 | AM5: 1 | AN5: 6 | AO5: 4 | AP5: 4 | AQ5: 4 | AR5: 7 | AS5: 1 | AT5: 1 | AU5: 4 | AV5: 1 | AW5: 4 | AX5: 3 | AY5: 5 | AZ5: 3 | BA5: 5
A6: Arun Kumar | C6: 1 | D6: 1 | E6: 1 | F6: 1 | G6: 1 | H6: 1 | I6: 1 | J6: 1 | K6: 1 | L6: 1 | M6: 1 | N6: 1 | O6: 1 | P6: 1 | Q6: 1 | R6: 1 | S6: 1 | T6: 1 | U6: 1 | V6: 1 | W6: 1 | X6: 1 | Y6: 1 | Z6: 1 | AA6: 1 | AB6: 1 | AC6: 1 | AD6: 1 | AE6: 1 | AF6: 1 | AG6: 1 | AH6: 1 | AI6: 1 | AJ6: 1 | AK6: 1 | AL6: 1 | AM6: 1 | AN6: 1 | AO6: 1 | AP6: 1 | AQ6: 1 | AR6: 1 | AS6: 1 | AT6: 1 | AU6: 1 | AV6: 1
A7: Ashraya H D | C7: 8 | D7: 8 | E7: 8 | F7: 7 | G7: 8 | H7: 8 | I7: 8 | J7: 7 | K7: 8 | L7: 8 | M7: 4 | N7: 6 | O7: 8 | P7: 7 | Q7: 7 | R7: 8 | S7: 4 | T7: 6 | U7: 6 | V7: 4 | W7: 4 | X7: 7 | Y7: 8 | Z7: 8 | AA7: 6 | AB7: 8 | AC7: 4 | AD7: 8 | AE7: 4 | AF7: 1 | AG7: 1 | AH7: 1 | AI7: 1 | AJ7: 4 | AK7: 4 | AL7: 4 | AM7: 3 | AN7: 7 | AO7: 7 | AP7: 2 | AQ7: 5 | AR7: 6 | AS7: 1 | AT7: 3 | AU7: 6 | AV7: 3 | AW7: 9 | AX7: 8 | AY7: 9 | AZ7: 7 | BA7: 6
A8: Jeet Doshi | C8: 6 | D8: 7 | E8: 7 | F8: 7 | G8: 7 | H8: 7 | I8: 7 | J8: 6 | K8: 2 | L8: 4 | M8: 2 | N8: 2 | O8: 4 | P8: 4 | Q8: 4 | R8: 2 | S8: 4 | T8: 3 | U8: 2 | V8: 2 | W8: 2 | X8: 4 | Y8: 4 | Z8: 1 | AA8: 3 | AB8: 2 | AC8: 1 | AD8: 3 | AE8: 5 | AF8: 1 | AG8: 1 | AH8: 1 | AI8: 1 | AJ8: 1 | AK8: 1 | AL8: 1 | AM8: 1 | AN8: 5 | AO8: 5 | AP8: 2 | AQ8: 4 | AR8: 6 | AS8: 1 | AT8: 1 | AU8: 5 | AV8: 1 | AW8: 4 | AX8: 6 | AY8: 7 | AZ8: 3 | BA8: 4
A9: Mahesh Kumar | C9: 4 | D9: 5 | E9: 7 | F9: 7 | G9: 7 | H9: 7 | I9: 7 | J9: 5 | K9: 3 | L9: 4 | M9: 5 | N9: 4 | O9: 5 | P9: 3 | Q9: 2 | R9: 2 | S9: 3 | T9: 3 | U9: 2 | V9: 4 | W9: 1 | X9: 1 | Y9: 1 | Z9: 3 | AA9: 3 | AB9: 5 | AC9: 2 | AD9: 2 | AE9: 1 | AF9: 1 | AG9: 1 | AH9: 1 | AI9: 1 | AJ9: 5 | AK9: 4 | AL9: 2 | AM9: 1 | AN9: 2 | AO9: 1 | AP9: 3 | AQ9: 4 | AR9: 7 | AS9: 4 | AT9: 1 | AU9: 5 | AV9: 1 | AW9: 4 | AX9: 5 | AY9: 6 | AZ9: 1 | BA9: 2
A10: Nilekha Repaka | C10: 7 | D10: 8 | E10: 8 | F10: 8 | G10: 8 | H10: 8 | I10: 8 | J10: 8 | K10: 8 | L10: 8 | M10: 8 | N10: 8 | O10: 6 | P10: 7 | Q10: 7 | R10: 7 | S10: 8 | T10: 7 | U10: 3 | V10: 5 | W10: 5 | X10: 5 | Y10: 4 | Z10: 5 | AA10: 4 | AB10: 7 | AC10: 6 | AD10: 6 | AE10: 4 | AF10: 5 | AG10: 1 | AH10: 1 | AI10: 1 | AJ10: 5 | AK10: 5 | AL10: 1 | AM10: 5 | AN10: 6 | AO10: 5 | AP10: 5 | AQ10: 6 | AR10: 7 | AS10: 3 | AT10: 5 | AU10: 5 | AV10: 5 | AW10: 8 | AX10: 7 | AY10: 9 | AZ10: 3 | BA10: 5
A11: Pawan Rathore | C11: 8 | D11: 8 | E11: 8 | F11: 7 | G11: 8 | H11: 8 | I11: 8 | J11: 8 | K11: 7 | L11: 8 | M11: 8 | N11: 8 | O11: 8 | P11: 7 | Q11: 5 | R11: 5 | S11: 5 | T11: 5 | U11: 5 | V11: 5 | W11: 4 | X11: 3 | Y11: 3 | Z11: 3 | AA11: 7 | AB11: 6 | AC11: 6 | AD11: 6 | AE11: 1 | AF11: 7 | AG11: 7 | AH11: 7 | AI11: 7 | AJ11: 7 | AK11: 7 | AL11: 7 | AM11: 4 | AN11: 5 | AO11: 5 | AP11: 4 | AQ11: 8 | AR11: 8 | AS11: 5 | AT11: 5 | AU11: 5 | AV11: 5 | AW11: 5 | AX11: 6 | AY11: 5 | AZ11: 3 | BA11: 2
A12: Priyesh Tiwari | C12: 7 | D12: 8 | E12: 8 | F12: 7 | G12: 8 | H12: 8 | I12: 9 | J12: 9 | K12: 7 | L12: 7 | M12: 6 | N12: 7 | O12: 7 | P12: 7 | Q12: 7 | R12: 4 | S12: 9 | T12: 6 | U12: 2 | V12: 2 | W12: 2 | X12: 6 | Y12: 5 | Z12: 1 | AA12: 4 | AB12: 8 | AC12: 1 | AD12: 1 | AE12: 7 | AF12: 1 | AG12: 1 | AH12: 1 | AI12: 1 | AJ12: 7 | AK12: 1 | AL12: 1 | AM12: 4 | AN12: 7 | AO12: 6 | AP12: 5 | AQ12: 7 | AR12: 8 | AS12: 4 | AT12: 1 | AU12: 7 | AV12: 1 | AW12: 8 | AX12: 7 | AY12: 9 | AZ12: 5 | BA12: 7
A13: Rahul Kumar | C13: 6 | D13: 8 | E13: 8 | F13: 8 | G13: 8 | H13: 8 | I13: 8 | J13: 4 | K13: 8 | L13: 8 | M13: 6 | N13: 8 | O13: 8 | P13: 7 | Q13: 8 | R13: 4 | S13: 6 | T13: 6 | U13: 2 | V13: 2 | W13: 2 | X13: 4 | Y13: 6 | Z13: 8 | AA13: 8 | AB13: 6 | AC13: 4 | AD13: 7 | AE13: 6 | AF13: 1 | AG13: 1 | AH13: 1 | AI13: 1 | AJ13: 4 | AK13: 4 | AL13: 4 | AM13: 4 | AN13: 8 | AO13: 6 | AP13: 4 | AQ13: 8 | AR13: 8 | AS13: 2 | AT13: 2 | AU13: 6 | AV13: 2 | AW13: 5 | AX13: 7 | AY13: 5 | AZ13: 4 | BA13: 5
A14: Ramkrishna Kadiya | C14: 6 | D14: 7 | E14: 8 | F14: 8 | G14: 8 | H14: 8 | I14: 8 | J14: 1 | K14: 4 | L14: 5 | M14: 1 | N14: 5 | O14: 7 | P14: 3 | Q14: 1 | R14: 4 | S14: 6 | T14: 4 | U14: 1 | V14: 1 | W14: 1 | X14: 1 | Y14: 7 | Z14: 7 | AA14: 4 | AB14: 7 | AC14: 1 | AD14: 4 | AE14: 7 | AF14: 1 | AG14: 1 | AH14: 1 | AI14: 1 | AJ14: 4 | AK14: 4 | AL14: 1 | AM14: 2 | AN14: 4 | AO14: 6 | AP14: 6 | AQ14: 6 | AR14: 6 | AS14: 1 | AT14: 1 | AU14: 6 | AV14: 1 | AW14: 8 | AX14: 7 | AY14: 8 | AZ14: 7 | BA14: 7
A15: Revanth Anguluri | C15: 6 | D15: 6 | E15: 8 | F15: 8 | G15: 8 | H15: 8 | I15: 8 | J15: 3 | K15: 7 | L15: 8 | M15: 7 | N15: 8 | O15: 8 | P15: 8 | Q15: 5 | R15: 4 | S15: 6 | T15: 6 | U15: 4 | V15: 6 | W15: 4 | X15: 4 | Y15: 7 | Z15: 8 | AA15: 8 | AB15: 4 | AC15: 2 | AD15: 2 | AE15: 7 | AF15: 1 | AG15: 1 | AH15: 1 | AI15: 1 | AJ15: 3 | AK15: 3 | AL15: 1 | AM15: 2 | AN15: 5 | AO15: 2 | AP15: 5 | AQ15: 8 | AR15: 7 | AS15: 2 | AT15: 1 | AU15: 7 | AV15: 1 | AW15: 3 | AX15: 5 | AY15: 4 | AZ15: 5 | BA15: 8
A16: Sagar Sable | C16: 6 | D16: 7 | E16: 8 | F16: 8 | G16: 8 | H16: 8 | I16: 8 | J16: 6 | K16: 8 | L16: 8 | M16: 8 | N16: 4 | O16: 6 | P16: 7 | Q16: 7 | R16: 5 | S16: 8 | T16: 9 | U16: 7 | V16: 4 | W16: 6 | X16: 4 | Y16: 6 | Z16: 6 | AA16: 6 | AB16: 6 | AC16: 4 | AD16: 6 | AE16: 6 | AF16: 4 | AG16: 4 | AH16: 4 | AI16: 4 | AJ16: 4 | AK16: 4 | AL16: 4 | AM16: 4 | AN16: 6 | AO16: 8 | AP16: 6 | AQ16: 8 | AR16: 8 | AS16: 4 | AT16: 6 | AU16: 6 | AV16: 4 | AW16: 5 | AX16: 5 | AY16: 6 | AZ16: 5 | BA16: 6
A17: Shreya Ramprakash | C17: 5 | D17: 6 | E17: 7 | F17: 7 | G17: 8 | H17: 8 | I17: 9 | J17: 1 | K17: 3 | L17: 7 | M17: 7 | N17: 4 | O17: 7 | P17: 7 | Q17: 4 | R17: 5 | S17: 9 | T17: 7 | U17: 5 | V17: 5 | W17: 4 | X17: 1 | Y17: 6 | Z17: 6 | AA17: 6 | AB17: 4 | AC17: 3 | AD17: 3 | AE17: 8 | AF17: 1 | AG17: 2 | AH17: 1 | AI17: 3 | AJ17: 5 | AK17: 4 | AL17: 1 | AM17: 4 | AN17: 2 | AO17: 3 | AP17: 6 | AQ17: 8 | AR17: 8 | AS17: 1 | AT17: 1 | AU17: 7 | AV17: 1 | AW17: 1 | AX17: 4 | AY17: 3 | AZ17: 4 | BA17: 6
A18: Shreyas Risodkar | C18: 6 | D18: 8 | E18: 8 | F18: 8 | G18: 8 | H18: 7 | I18: 9 | J18: 1 | K18: 5 | L18: 8 | M18: 8 | N18: 4 | O18: 7 | P18: 4 | Q18: 4 | R18: 4 | S18: 5 | T18: 5 | U18: 8 | V18: 5 | W18: 9 | X18: 6 | Y18: 7 | Z18: 1 | AA18: 5 | AB18: 8 | AC18: 5 | AD18: 7 | AE18: 6 | AF18: 1 | AG18: 1 | AH18: 1 | AI18: 1 | AJ18: 6 | AK18: 6 | AL18: 6 | AM18: 6 | AN18: 7 | AO18: 4 | AP18: 7 | AQ18: 8 | AR18: 8 | AS18: 4 | AT18: 3 | AU18: 7 | AV18: 2 | AW18: 8 | AX18: 8 | AY18: 7 | AZ18: 7 | BA18: 8
... A20: Swetha KJ | C20: 5 | D20: 6 | E20: 7 | F20: 7 | G20: 7 | H20: 8 | I20: 7 | J20: 1 | K20: 4 | L20: 6 | M20: 2 | N20: 5 | O20: 6 | P20: 7 | Q20: 3 | R20: 4 | S20: 5 | T20: 7 | U20: 5 | V20: 3 | W20: 3 | X20: 7 | Y20: 5 | Z20: 5 | AA20: 5 | AB20: 8 | AC20: 2 | AD20: 6 | AE20: 6 | AF20: 1 | AG20: 1 | AH20: 1 | AI20: 1 | AJ20: 5 | AK20: 3 | AL20: 3 | AM20: 5 | AN20: 6 | AO20: 3 | AP20: 8 | AQ20: 6 | AR20: 7 | AS20: 4 | AT20: 4 | AU20: 7 | AV20: 4 | AW20: 5 | AX20: 5 | AY20: 5 | AZ20: 6 | BA20: 6

Sheet Robot and Assistant
A1: Robot/Assistant - Install/Upgrade/Config | I1: Robot/Assistant - Feature/Delivery
A5: Expert | B5: Excellent | C5: Very good | D5: Good | E5: Above Average | F5: Average and Below | I5: Expert | J5: Excellent | K5: Very good | L5: Good | M5: Above Average | N5: Average and Below
A6: =IF('Skill Index'!E4=10,'Skill Index'!A4,"") | B6: =IF('Skill Index'!E4=9,'Skill Index'!A4,"") | C6: =IF('Skill Index'!E4=8,'Skill Index'!A4,"") -> Ankit Rajput | D6: =IF('Skill Index'!E4=7,'Skill Index'!A4,"") | E6: =IF('Skill Index'!E4=6,'Skill Index'!A4,"") | F6: =IF('Skill Index'!E4<6,'Skill Index'!A4,"") | I6: =IF('Skill Index'!F4=10,'Skill Index'!A4,"") | J6: =IF('Skill Index'!F4=9,'Skill Index'!A4,"") | K6: =IF('Skill Index'!F4=8,'Skill Index'!A4,"") | L6: =IF('Skill Index'!F4=7,'Skill Index'!A4,"") | M6: =IF('Skill Index'!F4=6,'Skill Index'!A4,"") -> Ankit Rajput | N6: =IF('Skill Index'!F4<6,'Skill Index'!A4,"")
A7: =IF('Skill Index'!E5=10,'Skill Index'!A5,"") | B7: =IF('Skill Index'!E5=9,'Skill Index'!A5,"") | C7: =IF('Skill Index'!E5=8,'Skill Index'!A5,"") | D7: =IF('Skill Index'!E5=7,'Skill Index'!A5,"") -> Anusha Gunda | E7: =IF('Skill Index'!E5=6,'Skill Index'!A5,"") | F7: =IF('Skill Index'!E5<6,'Skill Index'!A5,"") | I7: =IF('Skill Index'!F5=10,'Skill Index'!A5,"") | J7: =IF('Skill Index'!F5=9,'Skill Index'!A5,"") | K7: =IF('Skill Index'!F5=8,'Skill Index'!A5,"") | L7: =IF('Skill Index'!F5=7,'Skill Index'!A5,"") -> Anusha Gunda | M7: =IF('Skill Index'!F5=6,'Skill Index'!A5,"") | N7: =IF('Skill Index'!F5<6,'Skill Index'!A5,"")
A8: =IF('Skill Index'!E6=10,'Skill Index'!A6,"") | B8: =IF('Skill Index'!E6=9,'Skill Index'!A6,"") | C8: =IF('Skill Index'!E6=8,'Skill Index'!A6,"") | D8: =IF('Skill Index'!E6=7,'Skill Index'!A6,"") | E8: =IF('Skill Index'!E6=6,'Skill Index'!A6,"") | F8: =IF('Skill Index'!E6<6,'Skill Index'!A6,"") -> Arun Kumar | I8: =IF('Skill Index'!F6=10,'Skill Index'!A6,"") | J8: =IF('Skill Index'!F6=9,'Skill Index'!A6,"") | K8: =IF('Skill Index'!F6=8,'Skill Index'!A6,"") | L8: =IF('Skill Index'!F6=7,'Skill Index'!A6,"") | M8: =IF('Skill Index'!F6=6,'Skill Index'!A6,"") | N8: =IF('Skill Index'!F6<6,'Skill Index'!A6,"") -> Arun Kumar
A9: =IF('Skill Index'!E7=10,'Skill Index'!A7,"") | B9: =IF('Skill Index'!E7=9,'Skill Index'!A7,"") | C9: =IF('Skill Index'!E7=8,'Skill Index'!A7,"") -> Ashraya H D | D9: =IF('Skill Index'!E7=7,'Skill Index'!A7,"") | E9: =IF('Skill Index'!E7=6,'Skill Index'!A7,"") | F9: =IF('Skill Index'!E7<6,'Skill Index'!A7,"") | I9: =IF('Skill Index'!F7=10,'Skill Index'!A7,"") | J9: =IF('Skill Index'!F7=9,'Skill Index'!A7,"") | K9: =IF('Skill Index'!F7=8,'Skill Index'!A7,"") | L9: =IF('Skill Index'!F7=7,'Skill Index'!A7,"") -> Ashraya H D | M9: =IF('Skill Index'!F7=6,'Skill Index'!A7,"") | N9: =IF('Skill Index'!F7<6,'Skill Index'!A7,"")
A10: =IF('Skill Index'!E8=10,'Skill Index'!A8,"") | B10: =IF('Skill Index'!E8=9,'Skill Index'!A8,"") | C10: =IF('Skill Index'!E8=8,'Skill Index'!A8,"") | D10: =IF('Skill Index'!E8=7,'Skill Index'!A8,"") -> Jeet Doshi | E10: =IF('Skill Index'!E8=6,'Skill Index'!A8,"") | F10: =IF('Skill Index'!E8<6,'Skill Index'!A8,"") | I10: =IF('Skill Index'!F8=10,'Skill Index'!A8,"") | J10: =IF('Skill Index'!F8=9,'Skill Index'!A8,"") | K10: =IF('Skill Index'!F8=8,'Skill Index'!A8,"") | L10: =IF('Skill Index'!F8=7,'Skill Index'!A8,"") -> Jeet Doshi | M10: =IF('Skill Index'!F8=6,'Skill Index'!A8,"") | N10: =IF('Skill Index'!F8<6,'Skill Index'!A8,"")
A11: =IF('Skill Index'!E9=10,'Skill Index'!A9,"") | B11: =IF('Skill Index'!E9=9,'Skill Index'!A9,"") | C11: =IF('Skill Index'!E9=8,'Skill Index'!A9,"") | D11: =IF('Skill Index'!E9=7,'Skill Index'!A9,"") -> Mahesh Kumar | E11: =IF('Skill Index'!E9=6,'Skill Index'!A9,"") | F11: =IF('Skill Index'!E9<6,'Skill Index'!A9,"") | I11: =IF('Skill Index'!F9=10,'Skill Index'!A9,"") | J11: =IF('Skill Index'!F9=9,'Skill Index'!A9,"") | K11: =IF('Skill Index'!F9=8,'Skill Index'!A9,"") | L11: =IF('Skill Index'!F9=7,'Skill Index'!A9,"") -> Mahesh Kumar | M11: =IF('Skill Index'!F9=6,'Skill Index'!A9,"") | N11: =IF('Skill Index'!F9<6,'Skill Index'!A9,"")
A12: =IF('Skill Index'!E10=10,'Skill Index'!A10,"") | B12: =IF('Skill Index'!E10=9,'Skill Index'!A10,"") | C12: =IF('Skill Index'!E10=8,'Skill Index'!A10,"") -> Nilekha Repaka | D12: =IF('Skill Index'!E10=7,'Skill Index'!A10,"") | E12: =IF('Skill Index'!E10=6,'Skill Index'!A10,"") | F12: =IF('Skill Index'!E10<6,'Skill Index'!A10,"") | I12: =IF('Skill Index'!F10=10,'Skill Index'!A10,"") | J12: =IF('Skill Index'!F10=9,'Skill Index'!A10,"") | K12: =IF('Skill Index'!F10=8,'Skill Index'!A10,"") -> Nilekha Repaka | L12: =IF('Skill Index'!F10=7,'Skill Index'!A10,"") | M12: =IF('Skill Index'!F10=6,'Skill Index'!A10,"") | N12: =IF('Skill Index'!F10<6,'Skill Index'!A10,"")
A13: =IF('Skill Index'!E11=10,'Skill Index'!A11,"") | B13: =IF('Skill Index'!E11=9,'Skill Index'!A11,"") | C13: =IF('Skill Index'!E11=8,'Skill Index'!A11,"") -> Pawan Rathore | D13: =IF('Skill Index'!E11=7,'Skill Index'!A11,"") | E13: =IF('Skill Index'!E11=6,'Skill Index'!A11,"") | F13: =IF('Skill Index'!E11<6,'Skill Index'!A11,"") | I13: =IF('Skill Index'!F11=10,'Skill Index'!A11,"") | J13: =IF('Skill Index'!F11=9,'Skill Index'!A11,"") | K13: =IF('Skill Index'!F11=8,'Skill Index'!A11,"") | L13: =IF('Skill Index'!F11=7,'Skill Index'!A11,"") -> Pawan Rathore | M13: =IF('Skill Index'!F11=6,'Skill Index'!A11,"") | N13: =IF('Skill Index'!F11<6,'Skill Index'!A11,"")
A14: =IF('Skill Index'!E12=10,'Skill Index'!A12,"") | B14: =IF('Skill Index'!E12=9,'Skill Index'!A12,"") | C14: =IF('Skill Index'!E12=8,'Skill Index'!A12,"") -> Priyesh Tiwari | D14: =IF('Skill Index'!E12=7,'Skill Index'!A12,"") | E14: =IF('Skill Index'!E12=6,'Skill Index'!A12,"") | F14: =IF('Skill Index'!E12<6,'Skill Index'!A12,"") | I14: =IF('Skill Index'!F12=10,'Skill Index'!A12,"") | J14: =IF('Skill Index'!F12=9,'Skill Index'!A12,"") | K14: =IF('Skill Index'!F12=8,'Skill Index'!A12,"") | L14: =IF('Skill Index'!F12=7,'Skill Index'!A12,"") -> Priyesh Tiwari | M14: =IF('Skill Index'!F12=6,'Skill Index'!A12,"") | N14: =IF('Skill Index'!F12<6,'Skill Index'!A12,"")
A15: =IF('Skill Index'!E13=10,'Skill Index'!A13,"") | B15: =IF('Skill Index'!E13=9,'Skill Index'!A13,"") | C15: =IF('Skill Index'!E13=8,'Skill Index'!A13,"") -> Rahul Kumar | D15: =IF('Skill Index'!E13=7,'Skill Index'!A13,"") | E15: =IF('Skill Index'!E13=6,'Skill Index'!A13,"") | F15: =IF('Skill Index'!E13<6,'Skill Index'!A13,"") | I15: =IF('Skill Index'!F13=10,'Skill Index'!A13,"") | J15: =IF('Skill Index'!F13=9,'Skill Index'!A13,"") | K15: =IF('Skill Index'!F13=8,'Skill Index'!A13,"") -> Rahul Kumar | L15: =IF('Skill Index'!F13=7,'Skill Index'!A13,"") | M15: =IF('Skill Index'!F13=6,'Skill Index'!A13,"") | N15: =IF('Skill Index'!F13<6,'Skill Index'!A13,"")
A16: =IF('Skill Index'!E14=10,'Skill Index'!A14,"") | B16: =IF('Skill Index'!E14=9,'Skill Index'!A14,"") | C16: =IF('Skill Index'!E14=8,'Skill Index'!A14,"") -> Ramkrishna Kadiya | D16: =IF('Skill Index'!E14=7,'Skill Index'!A14,"") | E16: =IF('Skill Index'!E14=6,'Skill Index'!A14,"") | F16: =IF('Skill Index'!E14<6,'Skill Index'!A14,"") | I16: =IF('Skill Index'!F14=10,'Skill Index'!A14,"") | J16: =IF('Skill Index'!F14=9,'Skill Index'!A14,"") | K16: =IF('Skill Index'!F14=8,'Skill Index'!A14,"") -> Ramkrishna Kadiya | L16: =IF('Skill Index'!F14=7,'Skill Index'!A14,"") | M16: =IF('Skill Index'!F14=6,'Skill Index'!A14,"") | N16: =IF('Skill Index'!F14<6,'Skill Index'!A14,"")
A17: =IF('Skill Index'!E15=10,'Skill Index'!A15,"") | B17: =IF('Skill Index'!E15=9,'Skill Index'!A15,"") | C17: =IF('Skill Index'!E15=8,'Skill Index'!A15,"") -> Revanth Anguluri | D17: =IF('Skill Index'!E15=7,'Skill Index'!A15,"") | E17: =IF('Skill Index'!E15=6,'Skill Index'!A15,"") | F17: =IF('Skill Index'!E15<6,'Skill Index'!A15,"") | I17: =IF('Skill Index'!F15=10,'Skill Index'!A15,"") | J17: =IF('Skill Index'!F15=9,'Skill Index'!A15,"") | K17: =IF('Skill Index'!F15=8,'Skill Index'!A15,"") -> Revanth Anguluri | L17: =IF('Skill Index'!F15=7,'Skill Index'!A15,"") | M17: =IF('Skill Index'!F15=6,'Skill Index'!A15,"") | N17: =IF('Skill Index'!F15<6,'Skill Index'!A15,"")
... A22: =IF('Skill Index'!E20=10,'Skill Index'!A20,"") | B22: =IF('Skill Index'!E20=9,'Skill Index'!A20,"") | C22: =IF('Skill Index'!E20=8,'Skill Index'!A20,"") | D22: =IF('Skill Index'!E20=7,'Skill Index'!A20,"") -> Swetha KJ | E22: =IF('Skill Index'!E20=6,'Skill Index'!A20,"") | F22: =IF('Skill Index'!E20<6,'Skill Index'!A20,"") | I22: =IF('Skill Index'!F20=10,'Skill Index'!A20,"") | J22: =IF('Skill Index'!F20=9,'Skill Index'!A20,"") | K22: =IF('Skill Index'!F20=8,'Skill Index'!A20,"") | L22: =IF('Skill Index'!F20=7,'Skill Index'!A20,"") -> Swetha KJ | M22: =IF('Skill Index'!F20=6,'Skill Index'!A20,"") | N22: =IF('Skill Index'!F20<6,'Skill Index'!A20,"")

Sheet Studio Family
A1: Studio Family - Install/Upgrade/Config | I1: Studio Family - Feature/Delivery
A5: Expert | B5: Excellent | C5: Very good | D5: Good | E5: Above Average | F5: Average and Below | I5: Expert | J5: Excellent | K5: Very good | L5: Good | M5: Above Average | N5: Average and Below
A6: =IF('Skill Index'!G4=10,'Skill Index'!A4,"") | B6: =IF('Skill Index'!G4=9,'Skill Index'!A4,"") | C6: =IF('Skill Index'!G4=8,'Skill Index'!A4,"") -> Ankit Rajput | D6: =IF('Skill Index'!G4=7,'Skill Index'!A4,"") | E6: =IF('Skill Index'!G4=6,'Skill Index'!A4,"") | F6: =IF('Skill Index'!G4<6,'Skill Index'!A4,"") | I6: =IF('Skill Index'!H4=10,'Skill Index'!A4,"") | J6: =IF('Skill Index'!H4=9,'Skill Index'!A4,"") | K6: =IF('Skill Index'!H4=8,'Skill Index'!A4,"") | L6: =IF('Skill Index'!H4=7,'Skill Index'!A4,"") | M6: =IF('Skill Index'!H4=6,'Skill Index'!A4,"") -> Ankit Rajput | N6: =IF('Skill Index'!H4<6,'Skill Index'!A4,"")
A7: =IF('Skill Index'!G5=10,'Skill Index'!A5,"") | B7: =IF('Skill Index'!G5=9,'Skill Index'!A5,"") | C7: =IF('Skill Index'!G5=8,'Skill Index'!A5,"") | D7: =IF('Skill Index'!G5=7,'Skill Index'!A5,"") -> Anusha Gunda | E7: =IF('Skill Index'!G5=6,'Skill Index'!A5,"") | F7: =IF('Skill Index'!G5<6,'Skill Index'!A5,"") | I7: =IF('Skill Index'!H5=10,'Skill Index'!A5,"") | J7: =IF('Skill Index'!H5=9,'Skill Index'!A5,"") | K7: =IF('Skill Index'!H5=8,'Skill Index'!A5,"") | L7: =IF('Skill Index'!H5=7,'Skill Index'!A5,"") | M7: =IF('Skill Index'!H5=6,'Skill Index'!A5,"") -> Anusha Gunda | N7: =IF('Skill Index'!H5<6,'Skill Index'!A5,"")
A8: =IF('Skill Index'!G6=10,'Skill Index'!A6,"") | B8: =IF('Skill Index'!G6=9,'Skill Index'!A6,"") | C8: =IF('Skill Index'!G6=8,'Skill Index'!A6,"") | D8: =IF('Skill Index'!G6=7,'Skill Index'!A6,"") | E8: =IF('Skill Index'!G6=6,'Skill Index'!A6,"") | F8: =IF('Skill Index'!G6<6,'Skill Index'!A6,"") -> Arun Kumar | I8: =IF('Skill Index'!H6=10,'Skill Index'!A6,"") | J8: =IF('Skill Index'!H6=9,'Skill Index'!A6,"") | K8: =IF('Skill Index'!H6=8,'Skill Index'!A6,"") | L8: =IF('Skill Index'!H6=7,'Skill Index'!A6,"") | M8: =IF('Skill Index'!H6=6,'Skill Index'!A6,"") | N8: =IF('Skill Index'!H6<6,'Skill Index'!A6,"") -> Arun Kumar
A9: =IF('Skill Index'!G7=10,'Skill Index'!A7,"") | B9: =IF('Skill Index'!G7=9,'Skill Index'!A7,"") | C9: =IF('Skill Index'!G7=8,'Skill Index'!A7,"") -> Ashraya H D | D9: =IF('Skill Index'!G7=7,'Skill Index'!A7,"") | E9: =IF('Skill Index'!G7=6,'Skill Index'!A7,"") | F9: =IF('Skill Index'!G7<6,'Skill Index'!A7,"") | I9: =IF('Skill Index'!H7=10,'Skill Index'!A7,"") | J9: =IF('Skill Index'!H7=9,'Skill Index'!A7,"") | K9: =IF('Skill Index'!H7=8,'Skill Index'!A7,"") -> Ashraya H D | L9: =IF('Skill Index'!H7=7,'Skill Index'!A7,"") | M9: =IF('Skill Index'!H7=6,'Skill Index'!A7,"") | N9: =IF('Skill Index'!H7<6,'Skill Index'!A7,"")
A10: =IF('Skill Index'!G8=10,'Skill Index'!A8,"") | B10: =IF('Skill Index'!G8=9,'Skill Index'!A8,"") | C10: =IF('Skill Index'!G8=8,'Skill Index'!A8,"") | D10: =IF('Skill Index'!G8=7,'Skill Index'!A8,"") -> Jeet Doshi | E10: =IF('Skill Index'!G8=6,'Skill Index'!A8,"") | F10: =IF('Skill Index'!G8<6,'Skill Index'!A8,"") | I10: =IF('Skill Index'!H8=10,'Skill Index'!A8,"") | J10: =IF('Skill Index'!H8=9,'Skill Index'!A8,"") | K10: =IF('Skill Index'!H8=8,'Skill Index'!A8,"") | L10: =IF('Skill Index'!H8=7,'Skill Index'!A8,"") -> Jeet Doshi | M10: =IF('Skill Index'!H8=6,'Skill Index'!A8,"") | N10: =IF('Skill Index'!H8<6,'Skill Index'!A8,"")
A11: =IF('Skill Index'!G9=10,'Skill Index'!A9,"") | B11: =IF('Skill Index'!G9=9,'Skill Index'!A9,"") | C11: =IF('Skill Index'!G9=8,'Skill Index'!A9,"") | D11: =IF('Skill Index'!G9=7,'Skill Index'!A9,"") -> Mahesh Kumar | E11: =IF('Skill Index'!G9=6,'Skill Index'!A9,"") | F11: =IF('Skill Index'!G9<6,'Skill Index'!A9,"") | I11: =IF('Skill Index'!H9=10,'Skill Index'!A9,"") | J11: =IF('Skill Index'!H9=9,'Skill Index'!A9,"") | K11: =IF('Skill Index'!H9=8,'Skill Index'!A9,"") | L11: =IF('Skill Index'!H9=7,'Skill Index'!A9,"") -> Mahesh Kumar | M11: =IF('Skill Index'!H9=6,'Skill Index'!A9,"") | N11: =IF('Skill Index'!H9<6,'Skill Index'!A9,"")
A12: =IF('Skill Index'!G10=10,'Skill Index'!A10,"") | B12: =IF('Skill Index'!G10=9,'Skill Index'!A10,"") | C12: =IF('Skill Index'!G10=8,'Skill Index'!A10,"") -> Nilekha Repaka | D12: =IF('Skill Index'!G10=7,'Skill Index'!A10,"") | E12: =IF('Skill Index'!G10=6,'Skill Index'!A10,"") | F12: =IF('Skill Index'!G10<6,'Skill Index'!A10,"") | I12: =IF('Skill Index'!H10=10,'Skill Index'!A10,"") | J12: =IF('Skill Index'!H10=9,'Skill Index'!A10,"") | K12: =IF('Skill Index'!H10=8,'Skill Index'!A10,"") -> Nilekha Repaka | L12: =IF('Skill Index'!H10=7,'Skill Index'!A10,"") | M12: =IF('Skill Index'!H10=6,'Skill Index'!A10,"") | N12: =IF('Skill Index'!H10<6,'Skill Index'!A10,"")
A13: =IF('Skill Index'!G11=10,'Skill Index'!A11,"") | B13: =IF('Skill Index'!G11=9,'Skill Index'!A11,"") | C13: =IF('Skill Index'!G11=8,'Skill Index'!A11,"") -> Pawan Rathore | D13: =IF('Skill Index'!G11=7,'Skill Index'!A11,"") | E13: =IF('Skill Index'!G11=6,'Skill Index'!A11,"") | F13: =IF('Skill Index'!G11<6,'Skill Index'!A11,"") | I13: =IF('Skill Index'!H11=10,'Skill Index'!A11,"") | J13: =IF('Skill Index'!H11=9,'Skill Index'!A11,"") | K13: =IF('Skill Index'!H11=8,'Skill Index'!A11,"") -> Pawan Rathore | L13: =IF('Skill Index'!H11=7,'Skill Index'!A11,"") | M13: =IF('Skill Index'!H11=6,'Skill Index'!A11,"") | N13: =IF('Skill Index'!H11<6,'Skill Index'!A11,"")
A14: =IF('Skill Index'!G12=10,'Skill Index'!A12,"") | B14: =IF('Skill Index'!G12=9,'Skill Index'!A12,"") | C14: =IF('Skill Index'!G12=8,'Skill Index'!A12,"") -> Priyesh Tiwari | D14: =IF('Skill Index'!G12=7,'Skill Index'!A12,"") | E14: =IF('Skill Index'!G12=6,'Skill Index'!A12,"") | F14: =IF('Skill Index'!G12<6,'Skill Index'!A12,"") | I14: =IF('Skill Index'!H12=10,'Skill Index'!A12,"") | J14: =IF('Skill Index'!H12=9,'Skill Index'!A12,"") | K14: =IF('Skill Index'!H12=8,'Skill Index'!A12,"") -> Priyesh Tiwari | L14: =IF('Skill Index'!H12=7,'Skill Index'!A12,"") | M14: =IF('Skill Index'!H12=6,'Skill Index'!A12,"") | N14: =IF('Skill Index'!H12<6,'Skill Index'!A12,"")
A15: =IF('Skill Index'!G13=10,'Skill Index'!A13,"") | B15: =IF('Skill Index'!G13=9,'Skill Index'!A13,"") | C15: =IF('Skill Index'!G13=8,'Skill Index'!A13,"") -> Rahul Kumar | D15: =IF('Skill Index'!G13=7,'Skill Index'!A13,"") | E15: =IF('Skill Index'!G13=6,'Skill Index'!A13,"") | F15: =IF('Skill Index'!G13<6,'Skill Index'!A13,"") | I15: =IF('Skill Index'!H13=10,'Skill Index'!A13,"") | J15: =IF('Skill Index'!H13=9,'Skill Index'!A13,"") | K15: =IF('Skill Index'!H13=8,'Skill Index'!A13,"") -> Rahul Kumar | L15: =IF('Skill Index'!H13=7,'Skill Index'!A13,"") | M15: =IF('Skill Index'!H13=6,'Skill Index'!A13,"") | N15: =IF('Skill Index'!H13<6,'Skill Index'!A13,"")
A16: =IF('Skill Index'!G14=10,'Skill Index'!A14,"") | B16: =IF('Skill Index'!G14=9,'Skill Index'!A14,"") | C16: =IF('Skill Index'!G14=8,'Skill Index'!A14,"") -> Ramkrishna Kadiya | D16: =IF('Skill Index'!G14=7,'Skill Index'!A14,"") | E16: =IF('Skill Index'!G14=6,'Skill Index'!A14,"") | F16: =IF('Skill Index'!G14<6,'Skill Index'!A14,"") | I16: =IF('Skill Index'!H14=10,'Skill Index'!A14,"") | J16: =IF('Skill Index'!H14=9,'Skill Index'!A14,"") | K16: =IF('Skill Index'!H14=8,'Skill Index'!A14,"") -> Ramkrishna Kadiya | L16: =IF('Skill Index'!H14=7,'Skill Index'!A14,"") | M16: =IF('Skill Index'!H14=6,'Skill Index'!A14,"") | N16: =IF('Skill Index'!H14<6,'Skill Index'!A14,"")
A17: =IF('Skill Index'!G15=10,'Skill Index'!A15,"") | B17: =IF('Skill Index'!G15=9,'Skill Index'!A15,"") | C17: =IF('Skill Index'!G15=8,'Skill Index'!A15,"") -> Revanth Anguluri | D17: =IF('Skill Index'!G15=7,'Skill Index'!A15,"") | E17: =IF('Skill Index'!G15=6,'Skill Index'!A15,"") | F17: =IF('Skill Index'!G15<6,'Skill Index'!A15,"") | I17: =IF('Skill Index'!H15=10,'Skill Index'!A15,"") | J17: =IF('Skill Index'!H15=9,'Skill Index'!A15,"") | K17: =IF('Skill Index'!H15=8,'Skill Index'!A15,"") -> Revanth Anguluri | L17: =IF('Skill Index'!H15=7,'Skill Index'!A15,"") | M17: =IF('Skill Index'!H15=6,'Skill Index'!A15,"") | N17: =IF('Skill Index'!H15<6,'Skill Index'!A15,"")
... A22: =IF('Skill Index'!G20=10,'Skill Index'!A20,"") | B22: =IF('Skill Index'!G20=9,'Skill Index'!A20,"") | C22: =IF('Skill Index'!G20=8,'Skill Index'!A20,"") | D22: =IF('Skill Index'!G20=7,'Skill Index'!A20,"") -> Swetha KJ | E22: =IF('Skill Index'!G20=6,'Skill Index'!A20,"") | F22: =IF('Skill Index'!G20<6,'Skill Index'!A20,"") | I22: =IF('Skill Index'!H20=10,'Skill Index'!A20,"") | J22: =IF('Skill Index'!H20=9,'Skill Index'!A20,"") | K22: =IF('Skill Index'!H20=8,'Skill Index'!A20,"") -> Swetha KJ | L22: =IF('Skill Index'!H20=7,'Skill Index'!A20,"") | M22: =IF('Skill Index'!H20=6,'Skill Index'!A20,"") | N22: =IF('Skill Index'!H20<6,'Skill Index'!A20,"")

Sheet Orchestrator
A1: Orchestrator - Install/Upgrade/Config - Windows using MSI | I1: Orchestrator - Install/Upgrade/Config - PaaS | Q1: Orchestrator - Integrations (Cred Vault, AD) | Y1: Orchestrator - Feature/Delivery
A5: Expert | B5: Excellent | C5: Very good | D5: Good | E5: Above Average | F5: Average and Below | I5: Expert | J5: Excellent | K5: Very good | L5: Good | M5: Above Average | N5: Average and Below | Q5: Expert | R5: Excellent | S5: Very good | T5: Good | U5: Above Average | V5: Average and Below | Y5: Expert | Z5: Excellent | AA5: Very good | AB5: Good | AC5: Above Average | AD5: Average and Below
A6: =IF('Skill Index'!I4=10,'Skill Index'!A4,"") | B6: =IF('Skill Index'!I4=9,'Skill Index'!A4,"") -> Ankit Rajput | C6: =IF('Skill Index'!I4=8,'Skill Index'!A4,"") | D6: =IF('Skill Index'!I4=7,'Skill Index'!A4,"") | E6: =IF('Skill Index'!I4=6,'Skill Index'!A4,"") | F6: =IF('Skill Index'!I4<6,'Skill Index'!A4,"") | I6: =IF('Skill Index'!J4=10,'Skill Index'!A4,"") | J6: =IF('Skill Index'!J4=9,'Skill Index'!A4,"") | K6: =IF('Skill Index'!J4=8,'Skill Index'!A4,"") -> Ankit Rajput | L6: =IF('Skill Index'!J4=7,'Skill Index'!A4,"") | M6: =IF('Skill Index'!J4=6,'Skill Index'!A4,"") | N6: =IF('Skill Index'!J4<6,'Skill Index'!A4,"") | Q6: =IF('Skill Index'!K4=10,'Skill Index'!A4,"") | R6: =IF('Skill Index'!K4=9,'Skill Index'!A4,"") | S6: =IF('Skill Index'!K4=8,'Skill Index'!A4,"") | T6: =IF('Skill Index'!K4=7,'Skill Index'!A4,"") | U6: =IF('Skill Index'!K4=6,'Skill Index'!A4,"") -> Ankit Rajput | V6: =IF('Skill Index'!K4<6,'Skill Index'!A4,"") | Y6: =IF('Skill Index'!L4=10,'Skill Index'!A4,"") | Z6: =IF('Skill Index'!L4=9,'Skill Index'!A4,"") | AA6: =IF('Skill Index'!L4=8,'Skill Index'!A4,"") | AB6: =IF('Skill Index'!L4=7,'Skill Index'!A4,"") -> Ankit Rajput | AC6: =IF('Skill Index'!L4=6,'Skill Index'!A4,"") | AD6: =IF('Skill Index'!L4<6,'Skill Index'!A4,"")
A7: =IF('Skill Index'!I5=10,'Skill Index'!A5,"") | B7: =IF('Skill Index'!I5=9,'Skill Index'!A5,"") | C7: =IF('Skill Index'!I5=8,'Skill Index'!A5,"") -> Anusha Gunda | D7: =IF('Skill Index'!I5=7,'Skill Index'!A5,"") | E7: =IF('Skill Index'!I5=6,'Skill Index'!A5,"") | F7: =IF('Skill Index'!I5<6,'Skill Index'!A5,"") | I7: =IF('Skill Index'!J5=10,'Skill Index'!A5,"") | J7: =IF('Skill Index'!J5=9,'Skill Index'!A5,"") | K7: =IF('Skill Index'!J5=8,'Skill Index'!A5,"") | L7: =IF('Skill Index'!J5=7,'Skill Index'!A5,"") | M7: =IF('Skill Index'!J5=6,'Skill Index'!A5,"") | N7: =IF('Skill Index'!J5<6,'Skill Index'!A5,"") -> Anusha Gunda | Q7: =IF('Skill Index'!K5=10,'Skill Index'!A5,"") | R7: =IF('Skill Index'!K5=9,'Skill Index'!A5,"") | S7: =IF('Skill Index'!K5=8,'Skill Index'!A5,"") | T7: =IF('Skill Index'!K5=7,'Skill Index'!A5,"") | U7: =IF('Skill Index'!K5=6,'Skill Index'!A5,"") | V7: =IF('Skill Index'!K5<6,'Skill Index'!A5,"") -> Anusha Gunda | Y7: =IF('Skill Index'!L5=10,'Skill Index'!A5,"") | Z7: =IF('Skill Index'!L5=9,'Skill Index'!A5,"") | AA7: =IF('Skill Index'!L5=8,'Skill Index'!A5,"") -> Anusha Gunda | AB7: =IF('Skill Index'!L5=7,'Skill Index'!A5,"") | AC7: =IF('Skill Index'!L5=6,'Skill Index'!A5,"") | AD7: =IF('Skill Index'!L5<6,'Skill Index'!A5,"")
A8: =IF('Skill Index'!I6=10,'Skill Index'!A6,"") | B8: =IF('Skill Index'!I6=9,'Skill Index'!A6,"") | C8: =IF('Skill Index'!I6=8,'Skill Index'!A6,"") | D8: =IF('Skill Index'!I6=7,'Skill Index'!A6,"") | E8: =IF('Skill Index'!I6=6,'Skill Index'!A6,"") | F8: =IF('Skill Index'!I6<6,'Skill Index'!A6,"") -> Arun Kumar | I8: =IF('Skill Index'!J6=10,'Skill Index'!A6,"") | J8: =IF('Skill Index'!J6=9,'Skill Index'!A6,"") | K8: =IF('Skill Index'!J6=8,'Skill Index'!A6,"") | L8: =IF('Skill Index'!J6=7,'Skill Index'!A6,"") | M8: =IF('Skill Index'!J6=6,'Skill Index'!A6,"") | N8: =IF('Skill Index'!J6<6,'Skill Index'!A6,"") -> Arun Kumar | Q8: =IF('Skill Index'!K6=10,'Skill Index'!A6,"") | R8: =IF('Skill Index'!K6=9,'Skill Index'!A6,"") | S8: =IF('Skill Index'!K6=8,'Skill Index'!A6,"") | T8: =IF('Skill Index'!K6=7,'Skill Index'!A6,"") | U8: =IF('Skill Index'!K6=6,'Skill Index'!A6,"") | V8: =IF('Skill Index'!K6<6,'Skill Index'!A6,"") -> Arun Kumar | Y8: =IF('Skill Index'!L6=10,'Skill Index'!A6,"") | Z8: =IF('Skill Index'!L6=9,'Skill Index'!A6,"") | AA8: =IF('Skill Index'!L6=8,'Skill Index'!A6,"") | AB8: =IF('Skill Index'!L6=7,'Skill Index'!A6,"") | AC8: =IF('Skill Index'!L6=6,'Skill Index'!A6,"") | AD8: =IF('Skill Index'!L6<6,'Skill Index'!A6,"") -> Arun Kumar
A9: =IF('Skill Index'!I7=10,'Skill Index'!A7,"") | B9: =IF('Skill Index'!I7=9,'Skill Index'!A7,"") | C9: =IF('Skill Index'!I7=8,'Skill Index'!A7,"") -> Ashraya H D | D9: =IF('Skill Index'!I7=7,'Skill Index'!A7,"") | E9: =IF('Skill Index'!I7=6,'Skill Index'!A7,"") | F9: =IF('Skill Index'!I7<6,'Skill Index'!A7,"") | I9: =IF('Skill Index'!J7=10,'Skill Index'!A7,"") | J9: =IF('Skill Index'!J7=9,'Skill Index'!A7,"") | K9: =IF('Skill Index'!J7=8,'Skill Index'!A7,"") | L9: =IF('Skill Index'!J7=7,'Skill Index'!A7,"") -> Ashraya H D | M9: =IF('Skill Index'!J7=6,'Skill Index'!A7,"") | N9: =IF('Skill Index'!J7<6,'Skill Index'!A7,"") | Q9: =IF('Skill Index'!K7=10,'Skill Index'!A7,"") | R9: =IF('Skill Index'!K7=9,'Skill Index'!A7,"") | S9: =IF('Skill Index'!K7=8,'Skill Index'!A7,"") -> Ashraya H D | T9: =IF('Skill Index'!K7=7,'Skill Index'!A7,"") | U9: =IF('Skill Index'!K7=6,'Skill Index'!A7,"") | V9: =IF('Skill Index'!K7<6,'Skill Index'!A7,"") | Y9: =IF('Skill Index'!L7=10,'Skill Index'!A7,"") | Z9: =IF('Skill Index'!L7=9,'Skill Index'!A7,"") | AA9: =IF('Skill Index'!L7=8,'Skill Index'!A7,"") -> Ashraya H D | AB9: =IF('Skill Index'!L7=7,'Skill Index'!A7,"") | AC9: =IF('Skill Index'!L7=6,'Skill Index'!A7,"") | AD9: =IF('Skill Index'!L7<6,'Skill Index'!A7,"")
A10: =IF('Skill Index'!I8=10,'Skill Index'!A8,"") | B10: =IF('Skill Index'!I8=9,'Skill Index'!A8,"") | C10: =IF('Skill Index'!I8=8,'Skill Index'!A8,"") | D10: =IF('Skill Index'!I8=7,'Skill Index'!A8,"") -> Jeet Doshi | E10: =IF('Skill Index'!I8=6,'Skill Index'!A8,"") | F10: =IF('Skill Index'!I8<6,'Skill Index'!A8,"") | I10: =IF('Skill Index'!J8=10,'Skill Index'!A8,"") | J10: =IF('Skill Index'!J8=9,'Skill Index'!A8,"") | K10: =IF('Skill Index'!J8=8,'Skill Index'!A8,"") | L10: =IF('Skill Index'!J8=7,'Skill Index'!A8,"") | M10: =IF('Skill Index'!J8=6,'Skill Index'!A8,"") -> Jeet Doshi | N10: =IF('Skill Index'!J8<6,'Skill Index'!A8,"") | Q10: =IF('Skill Index'!K8=10,'Skill Index'!A8,"") | R10: =IF('Skill Index'!K8=9,'Skill Index'!A8,"") | S10: =IF('Skill Index'!K8=8,'Skill Index'!A8,"") | T10: =IF('Skill Index'!K8=7,'Skill Index'!A8,"") | U10: =IF('Skill Index'!K8=6,'Skill Index'!A8,"") | V10: =IF('Skill Index'!K8<6,'Skill Index'!A8,"") -> Jeet Doshi | Y10: =IF('Skill Index'!L8=10,'Skill Index'!A8,"") | Z10: =IF('Skill Index'!L8=9,'Skill Index'!A8,"") | AA10: =IF('Skill Index'!L8=8,'Skill Index'!A8,"") | AB10: =IF('Skill Index'!L8=7,'Skill Index'!A8,"") | AC10: =IF('Skill Index'!L8=6,'Skill Index'!A8,"") | AD10: =IF('Skill Index'!L8<6,'Skill Index'!A8,"") -> Jeet Doshi
A11: =IF('Skill Index'!I9=10,'Skill Index'!A9,"") | B11: =IF('Skill Index'!I9=9,'Skill Index'!A9,"") | C11: =IF('Skill Index'!I9=8,'Skill Index'!A9,"") | D11: =IF('Skill Index'!I9=7,'Skill Index'!A9,"") -> Mahesh Kumar | E11: =IF('Skill Index'!I9=6,'Skill Index'!A9,"") | F11: =IF('Skill Index'!I9<6,'Skill Index'!A9,"") | I11: =IF('Skill Index'!J9=10,'Skill Index'!A9,"") | J11: =IF('Skill Index'!J9=9,'Skill Index'!A9,"") | K11: =IF('Skill Index'!J9=8,'Skill Index'!A9,"") | L11: =IF('Skill Index'!J9=7,'Skill Index'!A9,"") | M11: =IF('Skill Index'!J9=6,'Skill Index'!A9,"") | N11: =IF('Skill Index'!J9<6,'Skill Index'!A9,"") -> Mahesh Kumar | Q11: =IF('Skill Index'!K9=10,'Skill Index'!A9,"") | R11: =IF('Skill Index'!K9=9,'Skill Index'!A9,"") | S11: =IF('Skill Index'!K9=8,'Skill Index'!A9,"") | T11: =IF('Skill Index'!K9=7,'Skill Index'!A9,"") | U11: =IF('Skill Index'!K9=6,'Skill Index'!A9,"") | V11: =IF('Skill Index'!K9<6,'Skill Index'!A9,"") -> Mahesh Kumar | Y11: =IF('Skill Index'!L9=10,'Skill Index'!A9,"") | Z11: =IF('Skill Index'!L9=9,'Skill Index'!A9,"") | AA11: =IF('Skill Index'!L9=8,'Skill Index'!A9,"") | AB11: =IF('Skill Index'!L9=7,'Skill Index'!A9,"") | AC11: =IF('Skill Index'!L9=6,'Skill Index'!A9,"") | AD11: =IF('Skill Index'!L9<6,'Skill Index'!A9,"") -> Mahesh Kumar
A12: =IF('Skill Index'!I10=10,'Skill Index'!A10,"") | B12: =IF('Skill Index'!I10=9,'Skill Index'!A10,"") | C12: =IF('Skill Index'!I10=8,'Skill Index'!A10,"") -> Nilekha Repaka | D12: =IF('Skill Index'!I10=7,'Skill Index'!A10,"") | E12: =IF('Skill Index'!I10=6,'Skill Index'!A10,"") | F12: =IF('Skill Index'!I10<6,'Skill Index'!A10,"") | I12: =IF('Skill Index'!J10=10,'Skill Index'!A10,"") | J12: =IF('Skill Index'!J10=9,'Skill Index'!A10,"") | K12: =IF('Skill Index'!J10=8,'Skill Index'!A10,"") -> Nilekha Repaka | L12: =IF('Skill Index'!J10=7,'Skill Index'!A10,"") | M12: =IF('Skill Index'!J10=6,'Skill Index'!A10,"") | N12: =IF('Skill Index'!J10<6,'Skill Index'!A10,"") | Q12: =IF('Skill Index'!K10=10,'Skill Index'!A10,"") | R12: =IF('Skill Index'!K10=9,'Skill Index'!A10,"") | S12: =IF('Skill Index'!K10=8,'Skill Index'!A10,"") -> Nilekha Repaka | T12: =IF('Skill Index'!K10=7,'Skill Index'!A10,"") | U12: =IF('Skill Index'!K10=6,'Skill Index'!A10,"") | V12: =IF('Skill Index'!K10<6,'Skill Index'!A10,"") | Y12: =IF('Skill Index'!L10=10,'Skill Index'!A10,"") | Z12: =IF('Skill Index'!L10=9,'Skill Index'!A10,"") | AA12: =IF('Skill Index'!L10=8,'Skill Index'!A10,"") -> Nilekha Repaka | AB12: =IF('Skill Index'!L10=7,'Skill Index'!A10,"") | AC12: =IF('Skill Index'!L10=6,'Skill Index'!A10,"") | AD12: =IF('Skill Index'!L10<6,'Skill Index'!A10,"")
A13: =IF('Skill Index'!I11=10,'Skill Index'!A11,"") | B13: =IF('Skill Index'!I11=9,'Skill Index'!A11,"") | C13: =IF('Skill Index'!I11=8,'Skill Index'!A11,"") -> Pawan Rathore | D13: =IF('Skill Index'!I11=7,'Skill Index'!A11,"") | E13: =IF('Skill Index'!I11=6,'Skill Index'!A11,"") | F13: =IF('Skill Index'!I11<6,'Skill Index'!A11,"") | I13: =IF('Skill Index'!J11=10,'Skill Index'!A11,"") | J13: =IF('Skill Index'!J11=9,'Skill Index'!A11,"") | K13: =IF('Skill Index'!J11=8,'Skill Index'!A11,"") -> Pawan Rathore | L13: =IF('Skill Index'!J11=7,'Skill Index'!A11,"") | M13: =IF('Skill Index'!J11=6,'Skill Index'!A11,"") | N13: =IF('Skill Index'!J11<6,'Skill Index'!A11,"") | Q13: =IF('Skill Index'!K11=10,'Skill Index'!A11,"") | R13: =IF('Skill Index'!K11=9,'Skill Index'!A11,"") | S13: =IF('Skill Index'!K11=8,'Skill Index'!A11,"") | T13: =IF('Skill Index'!K11=7,'Skill Index'!A11,"") -> Pawan Rathore | U13: =IF('Skill Index'!K11=6,'Skill Index'!A11,"") | V13: =IF('Skill Index'!K11<6,'Skill Index'!A11,"") | Y13: =IF('Skill Index'!L11=10,'Skill Index'!A11,"") | Z13: =IF('Skill Index'!L11=9,'Skill Index'!A11,"") | AA13: =IF('Skill Index'!L11=8,'Skill Index'!A11,"") -> Pawan Rathore | AB13: =IF('Skill Index'!L11=7,'Skill Index'!A11,"") | AC13: =IF('Skill Index'!L11=6,'Skill Index'!A11,"") | AD13: =IF('Skill Index'!L11<6,'Skill Index'!A11,"")
A14: =IF('Skill Index'!I12=10,'Skill Index'!A12,"") | B14: =IF('Skill Index'!I12=9,'Skill Index'!A12,"") -> Priyesh Tiwari | C14: =IF('Skill Index'!I12=8,'Skill Index'!A12,"") | D14: =IF('Skill Index'!I12=7,'Skill Index'!A12,"") | E14: =IF('Skill Index'!I12=6,'Skill Index'!A12,"") | F14: =IF('Skill Index'!I12<6,'Skill Index'!A12,"") | I14: =IF('Skill Index'!J12=10,'Skill Index'!A12,"") | J14: =IF('Skill Index'!J12=9,'Skill Index'!A12,"") -> Priyesh Tiwari | K14: =IF('Skill Index'!J12=8,'Skill Index'!A12,"") | L14: =IF('Skill Index'!J12=7,'Skill Index'!A12,"") | M14: =IF('Skill Index'!J12=6,'Skill Index'!A12,"") | N14: =IF('Skill Index'!J12<6,'Skill Index'!A12,"") | Q14: =IF('Skill Index'!K12=10,'Skill Index'!A12,"") | R14: =IF('Skill Index'!K12=9,'Skill Index'!A12,"") | S14: =IF('Skill Index'!K12=8,'Skill Index'!A12,"") | T14: =IF('Skill Index'!K12=7,'Skill Index'!A12,"") -> Priyesh Tiwari | U14: =IF('Skill Index'!K12=6,'Skill Index'!A12,"") | V14: =IF('Skill Index'!K12<6,'Skill Index'!A12,"") | Y14: =IF('Skill Index'!L12=10,'Skill Index'!A12,"") | Z14: =IF('Skill Index'!L12=9,'Skill Index'!A12,"") | AA14: =IF('Skill Index'!L12=8,'Skill Index'!A12,"") | AB14: =IF('Skill Index'!L12=7,'Skill Index'!A12,"") -> Priyesh Tiwari | AC14: =IF('Skill Index'!L12=6,'Skill Index'!A12,"") | AD14: =IF('Skill Index'!L12<6,'Skill Index'!A12,"")
A15: =IF('Skill Index'!I13=10,'Skill Index'!A13,"") | B15: =IF('Skill Index'!I13=9,'Skill Index'!A13,"") | C15: =IF('Skill Index'!I13=8,'Skill Index'!A13,"") -> Rahul Kumar | D15: =IF('Skill Index'!I13=7,'Skill Index'!A13,"") | E15: =IF('Skill Index'!I13=6,'Skill Index'!A13,"") | F15: =IF('Skill Index'!I13<6,'Skill Index'!A13,"") | I15: =IF('Skill Index'!J13=10,'Skill Index'!A13,"") | J15: =IF('Skill Index'!J13=9,'Skill Index'!A13,"") | K15: =IF('Skill Index'!J13=8,'Skill Index'!A13,"") | L15: =IF('Skill Index'!J13=7,'Skill Index'!A13,"") | M15: =IF('Skill Index'!J13=6,'Skill Index'!A13,"") | N15: =IF('Skill Index'!J13<6,'Skill Index'!A13,"") -> Rahul Kumar | Q15: =IF('Skill Index'!K13=10,'Skill Index'!A13,"") | R15: =IF('Skill Index'!K13=9,'Skill Index'!A13,"") | S15: =IF('Skill Index'!K13=8,'Skill Index'!A13,"") -> Rahul Kumar | T15: =IF('Skill Index'!K13=7,'Skill Index'!A13,"") | U15: =IF('Skill Index'!K13=6,'Skill Index'!A13,"") | V15: =IF('Skill Index'!K13<6,'Skill Index'!A13,"") | Y15: =IF('Skill Index'!L13=10,'Skill Index'!A13,"") | Z15: =IF('Skill Index'!L13=9,'Skill Index'!A13,"") | AA15: =IF('Skill Index'!L13=8,'Skill Index'!A13,"") -> Rahul Kumar | AB15: =IF('Skill Index'!L13=7,'Skill Index'!A13,"") | AC15: =IF('Skill Index'!L13=6,'Skill Index'!A13,"") | AD15: =IF('Skill Index'!L13<6,'Skill Index'!A13,"")
A16: =IF('Skill Index'!I14=10,'Skill Index'!A14,"") | B16: =IF('Skill Index'!I14=9,'Skill Index'!A14,"") | C16: =IF('Skill Index'!I14=8,'Skill Index'!A14,"") -> Ramkrishna Kadiya | D16: =IF('Skill Index'!I14=7,'Skill Index'!A14,"") | E16: =IF('Skill Index'!I14=6,'Skill Index'!A14,"") | F16: =IF('Skill Index'!I14<6,'Skill Index'!A14,"") | I16: =IF('Skill Index'!J14=10,'Skill Index'!A14,"") | J16: =IF('Skill Index'!J14=9,'Skill Index'!A14,"") | K16: =IF('Skill Index'!J14=8,'Skill Index'!A14,"") | L16: =IF('Skill Index'!J14=7,'Skill Index'!A14,"") | M16: =IF('Skill Index'!J14=6,'Skill Index'!A14,"") | N16: =IF('Skill Index'!J14<6,'Skill Index'!A14,"") -> Ramkrishna Kadiya | Q16: =IF('Skill Index'!K14=10,'Skill Index'!A14,"") | R16: =IF('Skill Index'!K14=9,'Skill Index'!A14,"") | S16: =IF('Skill Index'!K14=8,'Skill Index'!A14,"") | T16: =IF('Skill Index'!K14=7,'Skill Index'!A14,"") | U16: =IF('Skill Index'!K14=6,'Skill Index'!A14,"") | V16: =IF('Skill Index'!K14<6,'Skill Index'!A14,"") -> Ramkrishna Kadiya | Y16: =IF('Skill Index'!L14=10,'Skill Index'!A14,"") | Z16: =IF('Skill Index'!L14=9,'Skill Index'!A14,"") | AA16: =IF('Skill Index'!L14=8,'Skill Index'!A14,"") | AB16: =IF('Skill Index'!L14=7,'Skill Index'!A14,"") | AC16: =IF('Skill Index'!L14=6,'Skill Index'!A14,"") | AD16: =IF('Skill Index'!L14<6,'Skill Index'!A14,"") -> Ramkrishna Kadiya
A17: =IF('Skill Index'!I15=10,'Skill Index'!A15,"") | B17: =IF('Skill Index'!I15=9,'Skill Index'!A15,"") | C17: =IF('Skill Index'!I15=8,'Skill Index'!A15,"") -> Revanth Anguluri | D17: =IF('Skill Index'!I15=7,'Skill Index'!A15,"") | E17: =IF('Skill Index'!I15=6,'Skill Index'!A15,"") | F17: =IF('Skill Index'!I15<6,'Skill Index'!A15,"") | I17: =IF('Skill Index'!J15=10,'Skill Index'!A15,"") | J17: =IF('Skill Index'!J15=9,'Skill Index'!A15,"") | K17: =IF('Skill Index'!J15=8,'Skill Index'!A15,"") | L17: =IF('Skill Index'!J15=7,'Skill Index'!A15,"") | M17: =IF('Skill Index'!J15=6,'Skill Index'!A15,"") | N17: =IF('Skill Index'!J15<6,'Skill Index'!A15,"") -> Revanth Anguluri | Q17: =IF('Skill Index'!K15=10,'Skill Index'!A15,"") | R17: =IF('Skill Index'!K15=9,'Skill Index'!A15,"") | S17: =IF('Skill Index'!K15=8,'Skill Index'!A15,"") | T17: =IF('Skill Index'!K15=7,'Skill Index'!A15,"") -> Revanth Anguluri | U17: =IF('Skill Index'!K15=6,'Skill Index'!A15,"") | V17: =IF('Skill Index'!K15<6,'Skill Index'!A15,"") | Y17: =IF('Skill Index'!L15=10,'Skill Index'!A15,"") | Z17: =IF('Skill Index'!L15=9,'Skill Index'!A15,"") | AA17: =IF('Skill Index'!L15=8,'Skill Index'!A15,"") -> Revanth Anguluri | AB17: =IF('Skill Index'!L15=7,'Skill Index'!A15,"") | AC17: =IF('Skill Index'!L15=6,'Skill Index'!A15,"") | AD17: =IF('Skill Index'!L15<6,'Skill Index'!A15,"")
... A22: =IF('Skill Index'!I20=10,'Skill Index'!A20,"") | B22: =IF('Skill Index'!I20=9,'Skill Index'!A20,"") | C22: =IF('Skill Index'!I20=8,'Skill Index'!A20,"") | D22: =IF('Skill Index'!I20=7,'Skill Index'!A20,"") -> Swetha KJ | E22: =IF('Skill Index'!I20=6,'Skill Index'!A20,"") | F22: =IF('Skill Index'!I20<6,'Skill Index'!A20,"") | I22: =IF('Skill Index'!J20=10,'Skill Index'!A20,"") | J22: =IF('Skill Index'!J20=9,'Skill Index'!A20,"") | K22: =IF('Skill Index'!J20=8,'Skill Index'!A20,"") | L22: =IF('Skill Index'!J20=7,'Skill Index'!A20,"") | M22: =IF('Skill Index'!J20=6,'Skill Index'!A20,"") | N22: =IF('Skill Index'!J20<6,'Skill Index'!A20,"") -> Swetha KJ | Q22: =IF('Skill Index'!K20=10,'Skill Index'!A20,"") | R22: =IF('Skill Index'!K20=9,'Skill Index'!A20,"") | S22: =IF('Skill Index'!K20=8,'Skill Index'!A20,"") | T22: =IF('Skill Index'!K20=7,'Skill Index'!A20,"") | U22: =IF('Skill Index'!K20=6,'Skill Index'!A20,"") | V22: =IF('Skill Index'!K20<6,'Skill Index'!A20,"") -> Swetha KJ | Y22: =IF('Skill Index'!L20=10,'Skill Index'!A20,"") | Z22: =IF('Skill Index'!L20=9,'Skill Index'!A20,"") | AA22: =IF('Skill Index'!L20=8,'Skill Index'!A20,"") | AB22: =IF('Skill Index'!L20=7,'Skill Index'!A20,"") | AC22: =IF('Skill Index'!L20=6,'Skill Index'!A20,"") -> Swetha KJ | AD22: =IF('Skill Index'!L20<6,'Skill Index'!A20,"")

Sheet HAA
A1: HAA - Install/Upgrade/Config
A5: Expert | B5: Excellent | C5: Very good | D5: Good | E5: Above Average | F5: Average and Below
A6: =IF('Skill Index'!M4=10,'Skill Index'!A4,"") | B6: =IF('Skill Index'!M4=9,'Skill Index'!A4,"") | C6: =IF('Skill Index'!M4=8,'Skill Index'!A4,"") | D6: =IF('Skill Index'!M4=7,'Skill Index'!A4,"") | E6: =IF('Skill Index'!M4=6,'Skill Index'!A4,"") | F6: =IF('Skill Index'!M4<6,'Skill Index'!A4,"") -> Ankit Rajput
A7: =IF('Skill Index'!M5=10,'Skill Index'!A5,"") | B7: =IF('Skill Index'!M5=9,'Skill Index'!A5,"") | C7: =IF('Skill Index'!M5=8,'Skill Index'!A5,"") | D7: =IF('Skill Index'!M5=7,'Skill Index'!A5,"") | E7: =IF('Skill Index'!M5=6,'Skill Index'!A5,"") | F7: =IF('Skill Index'!M5<6,'Skill Index'!A5,"") -> Anusha Gunda
A8: =IF('Skill Index'!M6=10,'Skill Index'!A6,"") | B8: =IF('Skill Index'!M6=9,'Skill Index'!A6,"") | C8: =IF('Skill Index'!M6=8,'Skill Index'!A6,"") | D8: =IF('Skill Index'!M6=7,'Skill Index'!A6,"") | E8: =IF('Skill Index'!M6=6,'Skill Index'!A6,"") | F8: =IF('Skill Index'!M6<6,'Skill Index'!A6,"") -> Arun Kumar
A9: =IF('Skill Index'!M7=10,'Skill Index'!A7,"") | B9: =IF('Skill Index'!M7=9,'Skill Index'!A7,"") | C9: =IF('Skill Index'!M7=8,'Skill Index'!A7,"") | D9: =IF('Skill Index'!M7=7,'Skill Index'!A7,"") | E9: =IF('Skill Index'!M7=6,'Skill Index'!A7,"") | F9: =IF('Skill Index'!M7<6,'Skill Index'!A7,"") -> Ashraya H D
A10: =IF('Skill Index'!M8=10,'Skill Index'!A8,"") | B10: =IF('Skill Index'!M8=9,'Skill Index'!A8,"") | C10: =IF('Skill Index'!M8=8,'Skill Index'!A8,"") | D10: =IF('Skill Index'!M8=7,'Skill Index'!A8,"") | E10: =IF('Skill Index'!M8=6,'Skill Index'!A8,"") | F10: =IF('Skill Index'!M8<6,'Skill Index'!A8,"") -> Jeet Doshi
A11: =IF('Skill Index'!M9=10,'Skill Index'!A9,"") | B11: =IF('Skill Index'!M9=9,'Skill Index'!A9,"") | C11: =IF('Skill Index'!M9=8,'Skill Index'!A9,"") | D11: =IF('Skill Index'!M9=7,'Skill Index'!A9,"") | E11: =IF('Skill Index'!M9=6,'Skill Index'!A9,"") | F11: =IF('Skill Index'!M9<6,'Skill Index'!A9,"") -> Mahesh Kumar
A12: =IF('Skill Index'!M10=10,'Skill Index'!A10,"") | B12: =IF('Skill Index'!M10=9,'Skill Index'!A10,"") | C12: =IF('Skill Index'!M10=8,'Skill Index'!A10,"") -> Nilekha Repaka | D12: =IF('Skill Index'!M10=7,'Skill Index'!A10,"") | E12: =IF('Skill Index'!M10=6,'Skill Index'!A10,"") | F12: =IF('Skill Index'!M10<6,'Skill Index'!A10,"")
A13: =IF('Skill Index'!M11=10,'Skill Index'!A11,"") | B13: =IF('Skill Index'!M11=9,'Skill Index'!A11,"") | C13: =IF('Skill Index'!M11=8,'Skill Index'!A11,"") -> Pawan Rathore | D13: =IF('Skill Index'!M11=7,'Skill Index'!A11,"") | E13: =IF('Skill Index'!M11=6,'Skill Index'!A11,"") | F13: =IF('Skill Index'!M11<6,'Skill Index'!A11,"")
A14: =IF('Skill Index'!M12=10,'Skill Index'!A12,"") | B14: =IF('Skill Index'!M12=9,'Skill Index'!A12,"") | C14: =IF('Skill Index'!M12=8,'Skill Index'!A12,"") | D14: =IF('Skill Index'!M12=7,'Skill Index'!A12,"") | E14: =IF('Skill Index'!M12=6,'Skill Index'!A12,"") -> Priyesh Tiwari | F14: =IF('Skill Index'!M12<6,'Skill Index'!A12,"")
A15: =IF('Skill Index'!M13=10,'Skill Index'!A13,"") | B15: =IF('Skill Index'!M13=9,'Skill Index'!A13,"") | C15: =IF('Skill Index'!M13=8,'Skill Index'!A13,"") | D15: =IF('Skill Index'!M13=7,'Skill Index'!A13,"") | E15: =IF('Skill Index'!M13=6,'Skill Index'!A13,"") -> Rahul Kumar | F15: =IF('Skill Index'!M13<6,'Skill Index'!A13,"")
A16: =IF('Skill Index'!M14=10,'Skill Index'!A14,"") | B16: =IF('Skill Index'!M14=9,'Skill Index'!A14,"") | C16: =IF('Skill Index'!M14=8,'Skill Index'!A14,"") | D16: =IF('Skill Index'!M14=7,'Skill Index'!A14,"") | E16: =IF('Skill Index'!M14=6,'Skill Index'!A14,"") | F16: =IF('Skill Index'!M14<6,'Skill Index'!A14,"") -> Ramkrishna Kadiya
A17: =IF('Skill Index'!M15=10,'Skill Index'!A15,"") | B17: =IF('Skill Index'!M15=9,'Skill Index'!A15,"") | C17: =IF('Skill Index'!M15=8,'Skill Index'!A15,"") | D17: =IF('Skill Index'!M15=7,'Skill Index'!A15,"") -> Revanth Anguluri | E17: =IF('Skill Index'!M15=6,'Skill Index'!A15,"") | F17: =IF('Skill Index'!M15<6,'Skill Index'!A15,"")
... A22: =IF('Skill Index'!M20=10,'Skill Index'!A20,"") | B22: =IF('Skill Index'!M20=9,'Skill Index'!A20,"") | C22: =IF('Skill Index'!M20=8,'Skill Index'!A20,"") | D22: =IF('Skill Index'!M20=7,'Skill Index'!A20,"") | E22: =IF('Skill Index'!M20=6,'Skill Index'!A20,"") | F22: =IF('Skill Index'!M20<6,'Skill Index'!A20,"") -> Swetha KJ

Sheet Action Center
A1: Action Center - Install/Upgrade/Config | I1: Action Center - Feature/Delivery
A5: Expert | B5: Excellent | C5: Very good | D5: Good | E5: Above Average | F5: Average and Below | I5: Expert | J5: Excellent | K5: Very good | L5: Good | M5: Above Average | N5: Average and Below
A6: =IF('Skill Index'!N4=10,'Skill Index'!A4,"") | B6: =IF('Skill Index'!N4=9,'Skill Index'!A4,"") | C6: =IF('Skill Index'!N4=8,'Skill Index'!A4,"") -> Ankit Rajput | D6: =IF('Skill Index'!N4=7,'Skill Index'!A4,"") | E6: =IF('Skill Index'!N4=6,'Skill Index'!A4,"") | F6: =IF('Skill Index'!N4<6,'Skill Index'!A4,"") | I6: =IF('Skill Index'!O4=10,'Skill Index'!A4,"") | J6: =IF('Skill Index'!O4=9,'Skill Index'!A4,"") | K6: =IF('Skill Index'!O4=8,'Skill Index'!A4,"") -> Ankit Rajput | L6: =IF('Skill Index'!O4=7,'Skill Index'!A4,"") | M6: =IF('Skill Index'!O4=6,'Skill Index'!A4,"") | N6: =IF('Skill Index'!O4<6,'Skill Index'!A4,"")
A7: =IF('Skill Index'!N5=10,'Skill Index'!A5,"") | B7: =IF('Skill Index'!N5=9,'Skill Index'!A5,"") | C7: =IF('Skill Index'!N5=8,'Skill Index'!A5,"") | D7: =IF('Skill Index'!N5=7,'Skill Index'!A5,"") | E7: =IF('Skill Index'!N5=6,'Skill Index'!A5,"") -> Anusha Gunda | F7: =IF('Skill Index'!N5<6,'Skill Index'!A5,"") | I7: =IF('Skill Index'!O5=10,'Skill Index'!A5,"") | J7: =IF('Skill Index'!O5=9,'Skill Index'!A5,"") | K7: =IF('Skill Index'!O5=8,'Skill Index'!A5,"") -> Anusha Gunda | L7: =IF('Skill Index'!O5=7,'Skill Index'!A5,"") | M7: =IF('Skill Index'!O5=6,'Skill Index'!A5,"") | N7: =IF('Skill Index'!O5<6,'Skill Index'!A5,"")
A8: =IF('Skill Index'!N6=10,'Skill Index'!A6,"") | B8: =IF('Skill Index'!N6=9,'Skill Index'!A6,"") | C8: =IF('Skill Index'!N6=8,'Skill Index'!A6,"") | D8: =IF('Skill Index'!N6=7,'Skill Index'!A6,"") | E8: =IF('Skill Index'!N6=6,'Skill Index'!A6,"") | F8: =IF('Skill Index'!N6<6,'Skill Index'!A6,"") -> Arun Kumar | I8: =IF('Skill Index'!O6=10,'Skill Index'!A6,"") | J8: =IF('Skill Index'!O6=9,'Skill Index'!A6,"") | K8: =IF('Skill Index'!O6=8,'Skill Index'!A6,"") | L8: =IF('Skill Index'!O6=7,'Skill Index'!A6,"") | M8: =IF('Skill Index'!O6=6,'Skill Index'!A6,"") | N8: =IF('Skill Index'!O6<6,'Skill Index'!A6,"") -> Arun Kumar
